Workbook

Sheet Чек лист
A2: Краткое описание | D2: Статистика функционального тестирования | G2: Статистика Smoke тестирования | J2: Статистика тестирования UI
A3: Тип документа | B3: Чек лист + тест кейсы | D3: Всего проверок | E3: 19 | G3: Всего проверок | H3: 4 | J3: Всего проверок | K3: 11
A4: Проект | B4: Инфотекс тестовый проект | D4: =$A$10 -> В процессе | E4: 0 | G4: =$A$10 -> В процессе | H4: 0 | J4: =$A$10 -> В процессе | K4: 0
A5: Автор | B5: Ахметшин Марат | D5: =$A$11 -> Пройден | E5: 17 | G5: =$A$11 -> Пройден | H5: 4 | J5: =$A$11 -> Пройден | K5: 9
A6: Дата | B6: 46066 | D6: =$A$12 -> Не пройден | E6: 2 | G6: =$A$12 -> Не пройден | H6: 0 | J6: =$A$12 -> Не пройден | K6: 2
A7: Область применения | B7: Документ описывает перечень групп тестов, планируемых к выполнению для тестирования | D7: =$B$10 -> Trivial | E7: 0 | G7: =$B$10 -> Trivial | H7: 0 | J7: =$B$10 -> Trivial | K7: 1
D8: =$B$11 -> Minor | E8: 0 | G8: =$B$11 -> Minor | H8: 0 | J8: =$B$11 -> Minor | K8: 1
A9: Используемые обозначения статусов | B9: Используемые обозначения статусов багов | D9: =$B$12 -> Major | E9: 2 | G9: =$B$12 -> Major | H9: 0 | J9: =$B$12 -> Major | K9: 0
A10: В процессе | B10: Trivial | D10: =$B$13 -> Critical | E10: 0 | G10: =$B$13 -> Critical | H10: 0 | J10: =$B$13 -> Critical | K10: 0
A11: Пройден | B11: Minor | D11: =$B$14 -> Blocker | E11: 0 | G11: =$B$14 -> Blocker | H11: 0 | J11: =$B$14 -> Blocker | K11: 0
A12: Не пройден | B12: Major | D12: =$A$13 -> Заблокирован | E12: 0 | G12: =$A$13 -> Заблокирован | H12: 0 | J12: =$A$13 -> Заблокирован | K12: 0
A13: Заблокирован | B13: Critical | D13: =$A$14 -> Не тестировался | E13: 0 | G13: =$A$14 -> Не тестировался | H13: 0 | J13: =$A$14 -> Не тестировался | K13: 0
A14: Не тестировался | B14: Blocker | D14: =$A$15 -> Не реализован | E14: 0 | G14: =$A$15 -> Не реализован | H14: 0 | J14: =$A$15 -> Не реализован | K14: 0
A15: Не реализован | D15: Всего проверок осталось | E15: 0 | G15: Всего проверок осталось | H15: 0 | J15: Всего проверок осталось | K15: 0
D16: Процент выполнения | E16: 100 | G16: Процент выполнения | H16: 100 | J16: Процент выполнения | K16: 100
A18: Используемые обозначения приоритетов багов
A19: Высокий
A20: Средний
A21: Низкий
A26: ID | B26: Проверка | C26: Ожидаемый результат | D26: Результат
A27: Функциональное тестирование
A28: Позитивные
A29: CL-FUNC-POS-1 | B29: Создание запроса при заполнении минимума всех обязательных полей | C29: В БД появится соответствующая запись, а пользователю высветится окно ожидания | D29: =$A$11 -> Пройден
A30: CL-FUNC-POS-2 | B30: Создание запроса при заполнении минимума всех обязательных полей и дополнительно активации чекбокса и заполнение выпадающих полей | C30: В БД появится соответствующая запись, а пользователю высветится окно ожидания | D30: =$A$11 -> Пройден
A31: CL-FUNC-POS-3 | B31: Отправка запроса и получение данных от сторонней организации | C31: Пользователю должен отобразиться ответ в дочернем окне | D31: =$A$11 -> Пройден
A32: CL-FUNC-POS-4 | B32: Сохранение полученного от сторонней организации ответа в формате pdf | C32: По указанному пользователем пути сохрания появится файл с расширением pdf | D32: =$A$11 -> Пройден
A33: CL-FUNC-POS-5 | B33: Сохранение полученного от сторонней организации ответа в формате xml | C33: По указанному пользователем пути сохрания появится файл с расширением xml | D33: =$A$11 -> Пройден
A34: CL-FUNC-POS-6 | B34: Сохранение полученного от сторонней организации ответа в формате JSON | C34: По указанному пользователем пути сохрания появится файл с расширением json | D34: =$A$11 -> Пройден
A35: CL-FUNC-POS-7 | B35: Печатание полученных от сторонней организации данных при настроенном принтере | C35: Откроется системное окно печати | D35: =$A$11 -> Пройден
A36: CL-FUNC-POS-8 | B36: Проверка электронной подписи полученных от сторонней организации данных | C36: Пользователю высветится окно об успешном подтверждении подписи | D36: =$A$12 -> Не пройден
A37: Негативные
A38: CL-FUNC-NEG-1 | B38: Создание запроса при отсутствии заполнения ФИО | C38: Пользователю высветится подсказка об ошибке ввода данных | D38: =$A$11 -> Пройден
A39: CL-FUNC-NEG-2 | B39: Создание запроса при отсутствии заполнения ИНН | C39: Пользователю высветится подсказка об ошибке ввода данных | D39: =$A$12 -> Не пройден
A40: CL-FUNC-NEG-3 | B40: Создание запроса при отсутствии заполнения даты | C40: Пользователю высветится подсказка об ошибке ввода данных | D40: =$A$11 -> Пройден
A41: CL-FUNC-NEG-4 | B41: Создание запроса при невыбранном значении состояния ЭСП | C41: Пользователю высветится подсказка об ошибке ввода данных | D41: =$A$11 -> Пройден
A42: CL-FUNC-NEG-5 | B42: Отправка запроса с последующим выходом из окна ожидания | C42: Пользователю высветится вопрос о его намерении прервать транзакцию | D42: =$A$11 -> Пройден
A43: CL-FUNC-NEG-6 | B43: Создание запроса при заполнении всех нужных минимальных полей, и дополнительно активации чекбокса и заполнение не всех обязательных выпадающих полей | C43: Пользователю высветится подсказка об ошибке ввода данных | D43: =$A$11 -> Пройден
A44: CL-FUNC-NEG-7 | B44: Сохранение полученного от сторонней организации ответа в любом формате не являющимся pdf, xml, JSON | C44: Пользователю высветится подсказка об ошибке при сохранении файла | D44: =$A$11 -> Пройден
A45: CL-FUNC-NEG-8 | B45: Печатание полученных от сторонней организации данных при ненастроенном принтере | C45: Пользователю высветится подсказка об ошибке работы с принтером | D45: =$A$11 -> Пройден
A46: ID | B46: Проверка | C46: Ожидаемый результат | D46: Результат
...

Sheet Тест кейсы
E2: Комментарий: | F2: В задании сказано, что если что-то не обговорено, то можно додумать в системе функционал. 1. Я для интереса придумал, что у нас есть еще Apache Kafka, для отказоустойчивости и запросы к внешней системе идут через туда (при получении от фронтэнда запрос на данные от внешней системы ложится сообщение в топик organization.esp.requested). И потом приложение когда может под нагрузкой читает это сообщение и возвращает ответ, который потом фронтэнд подтянет. Даже если внешняя система не отвечает, то просто не будет подтвеждаться обработка сообщения - приложение чуть позже попробует снова. 2. И еще я додумал, что в приложении есть механизм аудирования таблиц бд и что тестировщик может по этим таблицам аудирования смотреть как все менялось. | G2: 3. И еще я додумал, что апи в приложении такое: { "LastName": "Ivanov", "FirstName": "Ivan", "MiddleName": "Ivanovich", "INN": "312422191601", "DateOfBirth": "31.01.2002", "ESP_Rights": { "From": "31.01.2026", "To": "31.01.2027" }, "ESP_Status": "NEW", "IdentityDocument": { "Enabled": true, "DocumentType": "Russian Federation Passport", "SeriesAndNumber": "1111 111111", "IssueDate": "31.01.2022" } } Они разные бывают насколько я знаю. Бывают camelCase snake_case, в данном случае тут PascalCase. Я у агрегатора ФССП даже видел апи на русском языке.
B3: Краткое описание
B4: Тип документа | C4: Тест кейсы | E4: Комментарий: | F4: Если гипотетически будет возможность выполнить только 40 - 50 % тест кейсов, то таковы мои мысли: Надо взять все Smoke кейсы - они выполняются быстро и проверяют важнейшие функции приложения, надо взять все негативные кейсы - по опыту разработчики там допускают ошибки чаще всего, и надо взять тест кейсы: ТС-3, ТС-4, ТС-8, потому что если функционал этих кейсов работает, то в случае багов в других, они дают обходной путь чтобы пользователь смог бы достичь своей цели и не получил бы негативного опыта. Как раз набирается 15 из 31 - 48 % тест кейсов.
B5: Проект | C5: Инфотекс тестовый проект
B6: Автор | C6: Ахметшин Марат
B7: Дата | C7: 46066
B8: Область применения | C8: Документ описывает тесты кейсы на каждый пункт из документа где описан чек лист
G11: Для удобства копирования при работе с UI и возможной работы через Postman тестовые данные приведены в JSON
B12: CL_ID | C12: test-case-ID | D12: Название | E12: Тип теста | F12: Предусловия | G12: Тестовые данные | H12: Шаги выполнения | I12: Ожидаемый результат | J12: Комментарий | K12: Аргументирование взятия тест кейса при возможности выполнения только 50 % тест кейсов
B13: Позитивные
B14: TC-1 | C14: ='Чек лист'!A29 -> CL-FUNC-POS-1 | D14: Создание запроса при заполнении минимума всех обязательных полей | E14: Позитивный | F14: Пользователь открыл приложение, выбрал интересующий его запрос, открыл форму запроса нажав кнопку: "Открыть форму запроса" | G14: { "LastName": "Ivanov", "FirstName": "Ivan", "MiddleName": "Ivanovich", "INN": "312422191601", "DateOfBirth": "31.01.2002", "ESP_Rights": { "From": "31.01.2026", "To": "31.01.2027" }, "ESP_Status": "NEW", "IdentityDocument": {} } | H14: 1. Заполнить поля: Фамилия, имя, отчество, ИНН, дата рождения, состояние ЭСП согласно тестовым данным. 2.Нажать кнопку: "Сохранить и отправить" | I14: 1. Высветилось окно ожидания 2. В БД в таблице, например, organization создана новая запись в статусе NEW | J14: Если все произошло слишком быстро, и статус не удалось отследить в БД в таблице, то можно проверить изменения статусов запроса в соответствующей таблице аудита | K14: Не берем, он частично покрывается тест кейсом TC-3
B15: TC-2 | C15: ='Чек лист'!A30 -> CL-FUNC-POS-2 | D15: Создание запроса при заполнении минимума всех обязательных полей и дополнительно активации чекбокса и заполнение выпадающих полей | E15: Позитивный | F15: Пользователь открыл приложение, выбрал интересующий его запрос, открыл форму запроса нажав кнопку: "Открыть форму запроса" | G15: { "LastName": "Ivanov", "FirstName": "Ivan", "MiddleName": "Ivanovich", "INN": "312422191601", "DateOfBirth": "31.01.2002", "ESP_Rights": { "From": "31.01.2026", "To": "31.01.2027" }, "ESP_Status": "NEW", "IdentityDocument": { "Enabled": true, "DocumentType": "Russian Federation Passport", "SeriesAndNumber": "1111 111111", "IssueDate": "31.01.2022" } } | H15: 1. Заполнить поля: Фамилия, имя, отчество, ИНН, дата рождения, состояние ЭСП, паспортные данные согласно тестовым данным. 2.Нажать кнопку: "Сохранить и отправить" | I15: 1. Высветилось окно ожидания 2. В БД в таблице, например, organization создана новая запись в статусе NEW 3. В топике Kafka (например, organization.esp.requested) появилось сообщение описывающее сделанный запрос 4. В БД в таблице organization в записи ответственной за данный запрос изменится статус с NEW на PENDING | J15: Если все произошло слишком быстро, и статус не удалось отследить в БД в таблице, то можно проверить изменения статусов запроса в соответствующей таблице аудита | K15: Не берем, он частично покрывается тест кейсом TC-3
B16: TC-3 | C16: ='Чек лист'!A31 -> CL-FUNC-POS-3 | D16: Отправка запроса в стороннюю организацию | E16: Позитивный | F16: Пользователь открыл приложение, выбрал интересующий его запрос, открыл форму запроса нажав кнопку: "Открыть форму запроса", ввел корректные данные, нажал "Сохранить и отправить", в kafka в топике organization.esp.requested уже появилось сообщение связанное с этим запросом | G16: { "LastName": "Ivanov", "FirstName": "Ivan", "MiddleName": "Ivanovich", "INN": "312422191601", "DateOfBirth": "31.01.2002", "ESP_Rights": { "From": "31.01.2026", "To": "31.01.2027" }, "ESP_Status": "NEW", "IdentityDocument": { "Enabled": true, "DocumentType": "Russian Federation Passport", "SeriesAndNumber": "1111 111111", "IssueDate": "31.01.2022" } } | I16: 1. Дождаться пока сервис сможет получить ответ от внешней организации 2.В UI в дочернем окне появлось сообщение об успешном получении данных 3. В БД в таблице organization у записи изменился статус на FINISHED | J16: Если все произошло слишком быстро, и статус не удалось отследить в БД в таблице, то можно проверить изменения статусов запроса в соответствующей таблице аудита | K16: Берем, он покрывает главный use-case
B17: TC-4 | C17: ='Чек лист'!A32 -> CL-FUNC-POS-4 | D17: Сохранение полученного от сторонней организации ответа в формате pdf | E17: Позитивный | F17: Пользователь открыл приложение, выбрал интересующий его запрос, открыл форму запроса нажав кнопку: "Открыть форму запроса", ввел корректные данные, нажал "Сохранить и отправить", получил ответ в дочернем окне | G17: { "LastName": "Ivanov", "FirstName": "Ivan", "MiddleName": "Ivanovich", "INN": "312422191601", "DateOfBirth": "31.01.2002", "ESP_Rights": { "From": "31.01.2026", "To": "31.01.2027" }, "ESP_Status": "NEW", "IdentityDocument": { "Enabled": true, "DocumentType": "Russian Federation Passport", "SeriesAndNumber": "1111 111111", "IssueDate": "31.01.2022" } } | H17: 1. Нажать на кнопку "Сохранить…" 2. Выбрать из предложенных опций pdf 3. Задать корректный путь до файла 4. Нажать кнопку "ОК" | I17: 1. В указанном месте на диске должен появиться рабочий файл pdf | K17: Берем, pdf один из самых популярных форматов
B18: TC-5 | C18: ='Чек лист'!A33 -> CL-FUNC-POS-5 | D18: Сохранение полученного от сторонней организации ответа в формате xml | E18: Позитивный | F18: Пользователь открыл приложение, выбрал интересующий его запрос, открыл форму запроса нажав кнопку: "Открыть форму запроса", ввел корректные данные, нажал "Сохранить и отправить", получил ответ в дочернем окне | G18: { "LastName": "Ivanov", "FirstName": "Ivan", "MiddleName": "Ivanovich", "INN": "312422191601", "DateOfBirth": "31.01.2002", "ESP_Rights": { "From": "31.01.2026", "To": "31.01.2027" }, "ESP_Status": "NEW", "IdentityDocument": { "Enabled": true, "DocumentType": "Russian Federation Passport", "SeriesAndNumber": "1111 111111", "IssueDate": "31.01.2022" } } | H18: 1. Нажать на кнопку "Сохранить…" 2. Выбрать из предложенных опций xml 3. Задать корректный путь до файла 4. Нажать кнопку "ОК" | I18: 1. В указанном месте на диске должен появиться рабочий файл xml | K18: Не берем, минимум протестируем pdf
B19: TC-6 | C19: ='Чек лист'!A34 -> CL-FUNC-POS-6 | D19: Сохранение полученного от сторонней организации ответа в формате JSON | E19: Позитивный | F19: Пользователь открыл приложение, выбрал интересующий его запрос, открыл форму запроса нажав кнопку: "Открыть форму запроса", ввел корректные данные, нажал "Сохранить и отправить", получил ответ в дочернем окне | G19: { "LastName": "Ivanov", "FirstName": "Ivan", "MiddleName": "Ivanovich", "INN": "312422191601", "DateOfBirth": "31.01.2002", "ESP_Rights": { "From": "31.01.2026", "To": "31.01.2027" }, "ESP_Status": "NEW", "IdentityDocument": { "Enabled": true, "DocumentType": "Russian Federation Passport", "SeriesAndNumber": "1111 111111", "IssueDate": "31.01.2022" } } | H19: 1. Нажать на кнопку "Сохранить…" 2. Выбрать из предложенных опций JSON 3. Задать корректный путь до файла 4. Нажать кнопку "ОК" | I19: 1. В указанном месте на диске должен появиться рабочий файл JSON | K19: Не берем, минимум протестируем pdf
B20: TC-7 | C20: ='Чек лист'!A35 -> CL-FUNC-POS-7 | D20: Печатание полученных от сторонней организации данных при настроенном принтере | E20: Позитивный | F20: Пользователь настроил и подключил к компьютеру принтер, открыл приложение, выбрал интересующий его запрос, открыл форму запроса нажав кнопку: "Открыть форму запроса", ввел корректные данные, нажал "Сохранить и отправить", получил ответ в дочернем окне | G20: { "LastName": "Ivanov", "FirstName": "Ivan", "MiddleName": "Ivanovich", "INN": "312422191601", "DateOfBirth": "31.01.2002", "ESP_Rights": { "From": "31.01.2026", "To": "31.01.2027" }, "ESP_Status": "NEW", "IdentityDocument": { "Enabled": true, "DocumentType": "Russian Federation Passport", "SeriesAndNumber": "1111 111111", "IssueDate": "31.01.2022" } } | H20: 1. Нажать на кнопку "Печать…" | I20: 1. Открылось системное диалоговое окно печати | K20: Не берем, пользователь может скачать pdf и распечатать сам
B21: TC-8 | C21: ='Чек лист'!A36 -> CL-FUNC-POS-8 | D21: Проверка электронной подписи полученных от сторонней организации данных | E21: Позитивный | F21: Пользователь открыл приложение, выбрал интересующий его запрос, открыл форму запроса нажав кнопку: "Открыть форму запроса", ввел корректные данные, нажал "Сохранить и отправить", получил ответ в дочернем окне | G21: { "LastName": "Ivanov", "FirstName": "Ivan", "MiddleName": "Ivanovich", "INN": "312422191601", "DateOfBirth": "31.01.2002", "ESP_Rights": { "From": "31.01.2026", "To": "31.01.2027" }, "ESP_Status": "NEW", "IdentityDocument": { "Enabled": true, "DocumentType": "Russian Federation Passport", "SeriesAndNumber": "1111 111111", "IssueDate": "31.01.2022" } } | H21: 1. Нажать на кнопку "Проверить подпись…" | I21: 1. Высветилось сообщение об успешной проверке электронной подписи | K21: Берем, это одна из самых важных функций. При работе с ЭСП и вообще важно знать, что ответ от надежного источника
B22: TC-9 | C22: ='Чек лист'!A49 -> CL-SMOKE-POS-1 | D22: Запустить приложение | E22: Позитивный | F22: Запущена машина с установленным приложением | H22: 1. Запустить приложение на рабочем столе | I22: 1. Появился интерфейс и основная панель | K22: Берем все Smoke тестирование и делаем его в первую очередь, так как оно быстрое
B23: TC-10 | C23: ='Чек лист'!A50 -> CL-SMOKE-POS-2 | D23: Отправить запрос | E23: Позитивный | F23: Пользователь открыл приложение, выбрал интересующий его запрос, открыл форму запроса нажав кнопку: "Открыть форму запроса", ввел корректные данные, | G23: { "LastName": "Ivanov", "FirstName": "Ivan", "MiddleName": "Ivanovich", "INN": "312422191601", "DateOfBirth": "31.01.2002", "ESP_Rights": { "From": "31.01.2026", "To": "31.01.2027" }, "ESP_Status": "NEW", "IdentityDocument": { "Enabled": true, "DocumentType": "Russian Federation Passport", "SeriesAndNumber": "1111 111111", "IssueDate": "31.01.2022" } } | H23: 1. Нажать "Сохранить и отправить" | I23: 1. Получен ответ в дочернем окне об успешном запросе | K23: Берем все Smoke тестирование и делаем его в первую очередь, так как оно быстрое
B24: TC-11 | C24: ='Чек лист'!A51 -> CL-SMOKE-POS-3 | D24: После отправки запроса выйти из формы | E24: Позитивный | F24: Пользователь открыл приложение, выбрал интересующий его запрос, открыл форму запроса нажав кнопку: "Открыть форму запроса", ввел корректные данные, нажал "Сохранить и отправить", получил ответ в дочернем окне | G24: { "LastName": "Ivanov", "FirstName": "Ivan", "MiddleName": "Ivanovich", "INN": "312422191601", "DateOfBirth": "31.01.2002", "ESP_Rights": { "From": "31.01.2026", "To": "31.01.2027" }, "ESP_Status": "NEW", "IdentityDocument": { "Enabled": true, "DocumentType": "Russian Federation Passport", "SeriesAndNumber": "1111 111111", "IssueDate": "31.01.2022" } } | H24: 1. Выйти из формы | I24: 1. Приложение работает в штатном режиме | K24: Берем все Smoke тестирование и делаем его в первую очередь, так как оно быстрое
B25: TC-12 | C25: ='Чек лист'!A57 -> CL-UI-POS-1 | D25: Проверить отсутствие орфографических ошибок | E25: Позитивный | F25: Пользователь открыл приложение, выбрал интересующий его запрос, открыл форму запроса нажав кнопку: "Открыть форму запроса" | H25: 1. Просмотреть текст на наличие ошибок | I25: 1. Ошибок не обнаружено | K25: Не берем, не столь критично как остальное
B26: TC-13 | C26: ='Чек лист'!A58 -> CL-UI-POS-2 | D26: Проверить во все ли предоставляемые поля форм можно вводить значения | E26: Позитивный | F26: Пользователь открыл приложение, выбрал интересующий его запрос, открыл форму запроса нажав кнопку: "Открыть форму запроса" | H26: 1. Поочередно во всех интерактивные места формы занести данные | I26: 1. Все поля формы откликаются и принимают корректно данные | K26: Не берем, это важно, но мест уже нет, фронтэндеры редко здесь допускают ошибки
B27: TC-14 | C27: ='Чек лист'!A59 -> CL-UI-POS-3 | D27: Проверить хорошо ли читается текст | E27: Позитивный | F27: Пользователь открыл приложение, выбрал интересующий его запрос, открыл форму запроса нажав кнопку: "Открыть форму запроса" | H27: 1. Просмотреть текст на наличие слишком мелкого шрифта или наличие сливающегося с фоном текста | I27: 1. Текст хорошо читаем | K27: Не берем, не столь критично как остальное
B28: TC-15 | C28: ='Чек лист'!A60 -> CL-UI-POS-4 | D28: Проверить что окно формы запроса оформлено в одном наборе цветов и выполнено в общей цветовой тематике приложения | E28: Позитивный | F28: Пользователь открыл приложение, выбрал интересующий его запрос, открыл форму запроса нажав кнопку: "Открыть форму запроса" | H28: 1. Просмотреть оформление формы | I28: 1. Цветовая гамма такая же как во всем остальном приложении | K28: Не берем, не столь критично как остальное
B29: TC-16 | C29: ='Чек лист'!A61 -> CL-UI-POS-5 | D29: Проверить корректность отображения изображений если они есть | E29: Позитивный | F29: Пользователь открыл приложение, выбрал интересующий его запрос, открыл форму запроса нажав кнопку: "Открыть форму запроса" | H29: 1. Проверить что изображения не съехали, имеют нужный размер и присутствуют | I29: 1. Все изображения в наличии на своих местах | K29: Не берем, не столь критично как остальное
B30: TC-17 | C30: ='Чек лист'!A62 -> CL-UI-POS-6 | D30: Проверить корректно ли окно отображается в разрешении 1920x1080 | E30: Позитивный | F30: Пользователь открыл приложение в разрешении 1920x1080, выбрал интересующий его запрос, открыл форму запроса нажав кнопку: "Открыть форму запроса" | H30: 1. Проверить что интерфейс корректно перестроился | I30: Все элементы интерфейса подстроились, аномалии, ошибки в позиционировании элементов отсутствуют | K30: Не берем, пользователь может изменить размер окна
B31: TC-18 | C31: ='Чек лист'!A63 -> CL-UI-POS-7 | D31: Проверить корректно ли окно отображается в разрешении 1366x768 | E31: Позитивный | F31: Пользователь открыл приложение в разрешении 1366x768, выбрал интересующий его запрос, открыл форму запроса нажав кнопку: "Открыть форму запроса" | H31: 1. Проверить что интерфейс корректно перестроился | I31: Все элементы интерфейса подстроились, аномалии, ошибки в позиционировании элементов отсутствуют | K31: Не берем, пользователь может изменить размер окна
B32: TC-19 | C32: ='Чек лист'!A64 -> CL-UI-POS-8 | D32: Проверить корректно ли окно отображается в разрешении 1536x864 | E32: Позитивный | F32: Пользователь открыл приложение в разрешении 1536x864, выбрал интересующий его запрос, открыл форму запроса нажав кнопку: "Открыть форму запроса" | H32: 1. Проверить что интерфейс корректно перестроился | I32: Все элементы интерфейса подстроились, аномалии, ошибки в позиционировании элементов отсутствуют | K32: Не берем, пользователь может изменить размер окна
B33: TC-20 | C33: ='Чек лист'!A65 -> CL-UI-POS-9 | D33: Проверить корректно ли окно отображается в разрешении 1280x720 | E33: Позитивный | F33: Пользователь открыл приложение в разрешении 1280x720, выбрал интересующий его запрос, открыл форму запроса нажав кнопку: "Открыть форму запроса" | H33: 1. Проверить что интерфейс корректно перестроился | I33: Все элементы интерфейса подстроились, аномалии, ошибки в позиционировании элементов отсутствуют | K33: Не берем, пользователь может изменить размер окна
B34: TC-21 | C34: ='Чек лист'!A66 -> CL-UI-POS-10 | D34: Проверить корректно ли окно отображается в разрешении 1440x900 | E34: Позитивный | F34: Пользователь открыл приложение в разрешении 1440x900, выбрал интересующий его запрос, открыл форму запроса нажав кнопку: "Открыть форму запроса" | H34: 1. Проверить что интерфейс корректно перестроился | I34: Все элементы интерфейса подстроились, аномалии, ошибки в позиционировании элементов отсутствуют | K34: Не берем, пользователь может изменить размер окна
B35: TC-22 | C35: ='Чек лист'!A67 -> CL-UI-POS-11 | D35: Проверить корректно ли окно отображается в разрешении 2560x1440 | E35: Позитивный | F35: Пользователь открыл приложение в разрешении 2560x1440, выбрал интересующий его запрос, открыл форму запроса нажав кнопку: "Открыть форму запроса" | H35: 1. Проверить что интерфейс корректно перестроился | I35: Все элементы интерфейса подстроились, аномалии, ошибки в позиционировании элементов отсутствуют | K35: Не берем, пользователь может изменить размер окна
E36: Негативные
B37: TC-23 | C37: ='Чек лист'!A38 -> CL-FUNC-NEG-1 | D37: Создание запроса при отсутствии заполнения ФИО | E37: Негативный | F37: Пользователь открыл приложение, выбрал интересующий его запрос, открыл форму запроса нажав кнопку: "Открыть форму запроса", ввел тестовые данные | G37: { "LastName": "", "FirstName": "", "MiddleName": "", "INN": "312422191601", "DateOfBirth": "31.01.2002", "ESP_Rights": { "From": "31.01.2026", "To": "31.01.2027" }, "ESP_Status": "NEW", "IdentityDocument": { "Enabled": true, "DocumentType": "Russian Federation Passport", "SeriesAndNumber": "1111 111111", "IssueDate": "31.01.2022" } } | H37: 1. Нажать "Сохранить и отправить" | I37: 1. Выведено сообщение: "ФИО обязательно к заполнению" | K37: Берем все негативные тест кейсы, так как разработчики часто допускают тут больше всего ошибок
B38: TC-24 | C38: ='Чек лист'!A39 -> CL-FUNC-NEG-2 | D38: Создание запроса при отсутствии заполнения ИНН | E38: Негативный | F38: Пользователь открыл приложение, выбрал интересующий его запрос, открыл форму запроса нажав кнопку: "Открыть форму запроса", ввел тестовые данные | G38: { "LastName": "Ivanov", "FirstName": "Ivan", "MiddleName": "Ivanovich", "INN": "", "DateOfBirth": "31.01.2002", "ESP_Rights": { "From": "31.01.2026", "To": "31.01.2027" }, "ESP_Status": "NEW", "IdentityDocument": { "Enabled": true, "DocumentType": "Russian Federation Passport", "SeriesAndNumber": "1111 111111", "IssueDate": "31.01.2022" } } | H38: 1. Нажать "Сохранить и отправить" | I38: 1. Выведено сообщение: "ИНН обязательно к заполнению" | K38: Берем все негативные тест кейсы, так как разработчики часто допускают тут больше всего ошибок
B39: TC-25 | C39: ='Чек лист'!A40 -> CL-FUNC-NEG-3 | D39: Создание запроса при отсутствии заполнения даты | E39: Негативный | F39: Пользователь открыл приложение, выбрал интересующий его запрос, открыл форму запроса нажав кнопку: "Открыть форму запроса", ввел тестовые данные | G39: { "LastName": "Ivanov", "FirstName": "Ivan", "MiddleName": "Ivanovich", "INN": "312422191601", "DateOfBirth": "", "ESP_Rights": { "From": "31.01.2026", "To": "31.01.2027" }, "ESP_Status": "NEW", "IdentityDocument": { "Enabled": true, "DocumentType": "Russian Federation Passport", "SeriesAndNumber": "1111 111111", "IssueDate": "31.01.2022" } } | H39: 1. Нажать "Сохранить и отправить" | I39: 1. Выведено сообщение: "дата рождения обязательна к заполнению" | K39: Берем все негативные тест кейсы, так как разработчики часто допускают тут больше всего ошибок
B40: TC-26 | C40: ='Чек лист'!A41 -> CL-FUNC-NEG-4 | D40: Создание запроса при невыбранном значении состояния ЭСП | E40: Негативный | F40: Пользователь открыл приложение, выбрал интересующий его запрос, открыл форму запроса нажав кнопку: "Открыть форму запроса", ввел тестовые данные | G40: { "LastName": "Ivanov", "FirstName": "Ivan", "MiddleName": "Ivanovich", "INN": "312422191601", "DateOfBirth": "31.01.2002", "ESP_Rights": { "From": "31.01.2026", "To": "31.01.2027" }, "ESP_Status": "", "IdentityDocument": { "Enabled": true, "DocumentType": "Russian Federation Passport", "SeriesAndNumber": "1111 111111", "IssueDate": "31.01.2022" } } | H40: 1. Не выбирать из предложенных опций состояние ЭСП 2. Нажать "Сохранить и отправить" | I40: 1. Выведено сообщение: "ЭСП обязательно к заполнению" | K40: Берем все негативные тест кейсы, так как разработчики часто допускают тут больше всего ошибок
B41: TC-27 | C41: ='Чек лист'!A42 -> CL-FUNC-NEG-5 | D41: Отправка запроса с последующим выходом из окна ожидания | E41: Негативный | F41: Пользователь открыл приложение, выбрал интересующий его запрос, открыл форму запроса нажав кнопку: "Открыть форму запроса", ввел корректные данные | G41: { "LastName": "Ivanov", "FirstName": "Ivan", "MiddleName": "Ivanovich", "INN": "312422191601", "DateOfBirth": "31.01.2002", "ESP_Rights": { "From": "31.01.2026", "To": "31.01.2027" }, "ESP_Status": "NEW", "IdentityDocument": { "Enabled": true, "DocumentType": "Russian Federation Passport", "SeriesAndNumber": "1111 111111", "IssueDate": "31.01.2022" } } | H41: 1. Нажать "Сохранить и отправить" 2. Не дожидаясь ответа выйти из окна ожидания | I41: 1. Выведено сообщение с текстом: "Вы уверены, что хотите выйти? Ваш запрос не будет обработан" | K41: Берем все негативные тест кейсы, так как разработчики часто допускают тут больше всего ошибок
B42: TC-28 | C42: ='Чек лист'!A43 -> CL-FUNC-NEG-6 | D42: Создание запроса при заполнении всех нужных минимальных полей, и дополнительно активации чекбокса и заполнение не всех обязательных выпадающих полей | E42: Негативный | F42: Пользователь открыл приложение, выбрал интересующий его запрос, открыл форму запроса нажав кнопку: "Открыть форму запроса", ввел тестовые данные | G42: { "LastName": "Ivanov", "FirstName": "Ivan", "MiddleName": "Ivanovich", "INN": "312422191601", "DateOfBirth": "31.01.2002", "ESP_Rights": { "From": "31.01.2026", "To": "31.01.2027" }, "ESP_Status": "NEW", "IdentityDocument": { "Enabled": true, "DocumentType": "Russian Federation Passport", "SeriesAndNumber": "", "IssueDate": "" } } | H42: 1. Нажать чекбокс "Документ удостоверяющий личность" 2. Не вводить паспотрные данные 2. Нажать "Сохранить и отправить" | I42: 1. Выведено сообщение: "Паспортные данные обязательны к заполнению" | K42: Берем все негативные тест кейсы, так как разработчики часто допускают тут больше всего ошибок
B43: TC-29 | C43: ='Чек лист'!A44 -> CL-FUNC-NEG-7 | D43: Сохранение полученного от сторонней организации ответа в любом формате не являющимся pdf, xml, JSON | E43: Негативный | F43: Пользователь открыл приложение, выбрал интересующий его запрос, открыл форму запроса нажав кнопку: "Открыть форму запроса", ввел корректные данные, дождался получения ответа от внешней системы | G43: { "LastName": "Ivanov", "FirstName": "Ivan", "MiddleName": "Ivanovich", "INN": "312422191601", "DateOfBirth": "31.01.2002", "ESP_Rights": { "From": "31.01.2026", "To": "31.01.2027" }, "ESP_Status": "NEW", "IdentityDocument": { "Enabled": true, "DocumentType": "Russian Federation Passport", "SeriesAndNumber": "1111 111111", "IssueDate": "31.01.2022" } } | H43: 1. В открывшемся окне нажать кнопку: "Сохранить..." 2. В открывшемся диалоговом окне выбрать любую опцию из JSON, XML, pdf 3. При указании пути, добавить в конце расширение не являющееся JSON, XML, pdf | I43: 1. Получено сообщение: "Указан неподдерживаемый формат файла" | K43: Берем все негативные тест кейсы, так как разработчики часто допускают тут больше всего ошибок
...

Sheet Баг репорты
B2: Краткое описание
B3: Тип документа | C3: Баг репорты
B4: Проект | C4: Инфотекс тестовый проект
B5: Автор | C5: Ахметшин Марат
B6: Дата | C6: 46066
B7: Область применения | C7: Документ описывает гипотетические баг репорты
F11: ID | G11: bug/KRK-90 | J11: ID | K11: bug/KRK-91 | N11: ID | O11: bug/KRK-92 | R11: ID | S11: bug/KRKW-243 | V11: ID | W11: bug/KRKW-244
F12: Описание | G12: Проверка электронной подписи полученных от сторонней организации данных | J12: Описание | K12: Окно некорректно отображается в разрешении 1536x864 | N12: Описание | O12: В БД нет таблицы organization | R12: Описание | S12: Кнопка "Сохранить и отправить" в окне "имя окна по ЧТЗ" имеет неправильный цвет | V12: Описание | W12: Отправляется запрос при незаполненном ИНН
F13: Версия | G13: app-1.8-SNAPSHOT | J13: Версия | K13: app-1.8-SNAPSHOT | N13: Версия | O13: app-1.8-SNAPSHOT | R13: Версия | S13: app-1.8-SNAPSHOT | V13: Версия | W13: app-1.8-SNAPSHOT
F14: Серьезность | G14: ='Чек лист'!$D$9 -> Major | J14: Серьезность | K14: ='Чек лист'!$D$8 -> Minor | N14: Серьезность | O14: ='Чек лист'!$D$9 -> Major | R14: Серьезность | S14: ='Чек лист'!$B$10 -> Trivial | V14: Серьезность | W14: ='Чек лист'!$D$9 -> Major
F15: Приоритет | G15: Высокий | J15: Приоритет | K15: ='Чек лист'!$A$20 -> Средний | N15: Приоритет | O15: Высокий | R15: Приоритет | S15: Высокий | V15: Приоритет | W15: Высокий
F16: Статус | G16: В работе | J16: Статус | K16: В работе | N16: Статус | O16: Исправлен | R16: Статус | S16: В работе | V16: Статус | W16: В работе
F17: Автор | G17: Ахметшин Марат Дамирович | J17: Автор | K17: Ахметшин Марат Дамирович | N17: Автор | O17: Ахметшин Марат Дамирович | R17: Автор | S17: Ахметшин Марат Дамирович | V17: Автор | W17: Ахметшин Марат Дамирович
F18: Исполнитель | G18: Дмитриев Иван Петрович | J18: Исполнитель | K18: Иванова Анна Владимировна | N18: Исполнитель | O18: Иванова Анна Владимировна | R18: Исполнитель | S18: Иванова Анна Владимировна | V18: Исполнитель | W18: Дмитриев Иван Петрович
F19: Шаги к воспроизведению | G19: 1. Открыть приложение 2. Выбрать интересующий его запрос 3. Открыть форму запроса нажав кнопку: "Открыть форму запроса", 4. Ввести корректные данные 5. Нажать "Сохранить и отправить", 6. Получить ответ в дочернем окне 7. Нажать на кнопку "Проверить подпись…" | J19: Шаги к воспроизведению | K19: 1. Открыть приложение в разрешении 1536x864 2. Выбрать интересующий его запрос 3. Открыть форму запроса нажав кнопку: "Открыть форму запроса", | N19: Шаги к воспроизведению | O19: 1. Открыть БД приложения 2. Произвести поиск таблицы organisations | R19: Шаги к воспроизведению | S19: 1. Открыть приложение 2. Выбрать интересующий его запрос 3. Открыть форму запроса нажав кнопку: "Открыть форму запроса", | V19: Шаги к воспроизведению | W19: 1. Открыть приложение 2. Выбрать интересующий его запрос 3. Открыть форму запроса нажав кнопку: "Открыть форму запроса", 4. Ввести корректные данные без ИНН 5. Нажать "Сохранить и отправить",
F20: Фактический результат | G20: Высветилось сообщение: "500 Internal Server Error" | J20: Фактический результат | K20: Кнопки :"Проверить подпись...", "Печать...", "Сохранить..." наехали на поля формы: "Дата рождения" и "Право использовать ЭСП предоставляется по" | N20: Фактический результат | O20: Кнопки :"Проверить подпись...", "Печать...", "Сохранить..." наехали на поля формы: "Дата рождения" и "Право использовать ЭСП предоставляется по" | R20: Фактический результат | S20: Кнопка "Сохранить и отправить" имеет серый цвет | V20: Фактический результат | W20: Приложение выводит на экран сообщение с ошибкой: "500 Internal Server Error"
F21: Ожидаемый результат | G21: Высветилось сообщение об успешной проверке электронной подписи | J21: Ожидаемый результат | K21: Все элементы интерфейса подстроились, аномалии, ошибки в позиционировании элементов отсутствуют | N21: Ожидаемый результат | O21: Таблица organisation присутсвует в БД, все поля на месте и имеют тип как в документации | R21: Ожидаемый результат | S21: Кнопка "Сохранить и отправить" имеет желтый цвет | V21: Ожидаемый результат | W21: Приложение выводит на экран сообщение с подсказкой: "ИНН обязательно к заполнению"
F22: Комментарии/вложения | G22: Данные для ввода: { "LastName": "Ivanov", "FirstName": "Ivan", "MiddleName": "Ivanovich", "INN": "312422191601", "DateOfBirth": "31.01.2002", "ESP_Rights": { "From": "31.01.2026", "To": "31.01.2027" }, "ESP_Status": "NEW", "IdentityDocument": { "Enabled": true, "DocumentType": "Russian Federation Passport", "SeriesAndNumber": "1111 111111", "IssueDate": "31.01.2022" } } здесь могло быть фото | J22: Комментарии/вложения | K22: здесь могло быть фото | N22: Комментарии/вложения | O22: здесь могло быть фото ER диаграммы | R22: Комментарии/вложения | S22: здесь могло быть фото окна | V22: Комментарии/вложения | W22: Данные для ввода: { "LastName": "Ivanov", "FirstName": "Ivan", "MiddleName": "Ivanovich", "INN": "", "DateOfBirth": "31.01.2002", "ESP_Rights": { "From": "31.01.2026", "To": "31.01.2027" }, "ESP_Status": "NEW", "IdentityDocument": { "Enabled": true, "DocumentType": "Russian Federation Passport", "SeriesAndNumber": "1111 111111", "IssueDate": "31.01.2022" } } здесь могло быть фото
F24: Обоснование: | G24: Приоритет высокий, а серьезность Major выбраны потому что функционал проверки электронной подписи очень важен. Покольку тут идет работа со способами оплаты, то надо гарантировать, что ответ пришел от добросовестной компании, а не от мошенника. | J24: Обоснование: | K24: Приоритет средний а серьезность minor - я додумал, что баг не ломает функционал, а просто кнопки немного наехали на поля форму, то есть пользоваться можно, но выглядит странно. Поэтому такой приоритет и серьезность. | N24: Обоснование: | O24: Приоритет высокий, а серьезность Major выбраны потому что раз нет таблицы, значит и функционал не работает совсем. Приложение не ломается полностью, просто функционал отправки запроса не работает. | R24: Обоснование: | S24: Trivial потому что ничего не ломает, а приоритет высокий, потому что приложение должно выглядеть красиво и придерживаться цветов бренда | V24: Обоснование: | W24: Серьезность Major а приоритет высокий, потому что это очень портит пользовательский опыт. Человек просто ИНН забыл ввести, а у него 500 ошибка
